2025-09-24 13:11:34,878 ERROR: Exception on /register [POST] [in C:\Users\Oleks PC\.virtualenvs\xednix-backend-NLhseXCO\Lib\site-packages\flask\app.py:875]
Traceback (most recent call last):
  File "C:\Users\Oleks PC\.virtualenvs\xednix-backend-NLhseXCO\Lib\site-packages\flask\app.py", line 1511, in wsgi_app
    response = self.full_dispatch_request()
  File "C:\Users\Oleks PC\.virtualenvs\xednix-backend-NLhseXCO\Lib\site-packages\flask\app.py", line 919, in full_dispatch_request
    rv = self.handle_user_exception(e)
  File "C:\Users\Oleks PC\.virtualenvs\xednix-backend-NLhseXCO\Lib\site-packages\flask_cors\extension.py", line 176, in wrapped_function
    return cors_after_request(app.make_response(f(*args, **kwargs)))
                                                ~^^^^^^^^^^^^^^^^^
  File "C:\Users\Oleks PC\.virtualenvs\xednix-backend-NLhseXCO\Lib\site-packages\flask\app.py", line 917, in full_dispatch_request
    rv = self.dispatch_request()
  File "C:\Users\Oleks PC\.virtualenvs\xednix-backend-NLhseXCO\Lib\site-packages\flask\app.py", line 902, in dispatch_request
    return self.ensure_sync(self.view_functions[rule.endpoint])(**view_args)  # type: ignore[no-any-return]
           ~~~~~~~~~~~~~~~~~~~~~~~~~~~~~~~~~~~~~~~~~~~~~~~~~~~~^^^^^^^^^^^^^
  File "D:\projects\Xednix\xednix-backend\routes.py", line 12, in register
    data = request.get_json()
           ^^^^^^^
NameError: name 'request' is not defined
2025-09-24 13:37:14,011 ERROR: Exception on /register [POST] [in C:\Users\Oleks PC\.virtualenvs\xednix-backend-NLhseXCO\Lib\site-packages\flask\app.py:875]
Traceback (most recent call last):
  File "C:\Users\Oleks PC\.virtualenvs\xednix-backend-NLhseXCO\Lib\site-packages\flask\app.py", line 1511, in wsgi_app
    response = self.full_dispatch_request()
  File "C:\Users\Oleks PC\.virtualenvs\xednix-backend-NLhseXCO\Lib\site-packages\flask\app.py", line 919, in full_dispatch_request
    rv = self.handle_user_exception(e)
  File "C:\Users\Oleks PC\.virtualenvs\xednix-backend-NLhseXCO\Lib\site-packages\flask_cors\extension.py", line 176, in wrapped_function
    return cors_after_request(app.make_response(f(*args, **kwargs)))
                                                ~^^^^^^^^^^^^^^^^^
  File "C:\Users\Oleks PC\.virtualenvs\xednix-backend-NLhseXCO\Lib\site-packages\flask\app.py", line 917, in full_dispatch_request
    rv = self.dispatch_request()
  File "C:\Users\Oleks PC\.virtualenvs\xednix-backend-NLhseXCO\Lib\site-packages\flask\app.py", line 902, in dispatch_request
    return self.ensure_sync(self.view_functions[rule.endpoint])(**view_args)  # type: ignore[no-any-return]
           ~~~~~~~~~~~~~~~~~~~~~~~~~~~~~~~~~~~~~~~~~~~~~~~~~~~~^^^^^^^^^^^^^
  File "D:\projects\Xednix\xednix-backend\routes.py", line 12, in register
    data = request.get_json()
           ^^^^^^^
NameError: name 'request' is not defined
2025-09-24 13:39:41,777 ERROR: Exception on /register [POST] [in C:\Users\Oleks PC\.virtualenvs\xednix-backend-NLhseXCO\Lib\site-packages\flask\app.py:875]
Traceback (most recent call last):
  File "C:\Users\Oleks PC\.virtualenvs\xednix-backend-NLhseXCO\Lib\site-packages\sqlalchemy\engine\base.py", line 1967, in _exec_single_context
    self.dialect.do_execute(
    ~~~~~~~~~~~~~~~~~~~~~~~^
        cursor, str_statement, effective_parameters, context
        ^^^^^^^^^^^^^^^^^^^^^^^^^^^^^^^^^^^^^^^^^^^^^^^^^^^^
    )
    ^
  File "C:\Users\Oleks PC\.virtualenvs\xednix-backend-NLhseXCO\Lib\site-packages\sqlalchemy\engine\default.py", line 951, in do_execute
    cursor.execute(statement, parameters)
    ~~~~~~~~~~~~~~^^^^^^^^^^^^^^^^^^^^^^^
psycopg2.errors.UndefinedTable: relation "user" does not exist
LINE 2: FROM "user" 
             ^


The above exception was the direct cause of the following exception:

Traceback (most recent call last):
  File "C:\Users\Oleks PC\.virtualenvs\xednix-backend-NLhseXCO\Lib\site-packages\flask\app.py", line 1511, in wsgi_app
    response = self.full_dispatch_request()
  File "C:\Users\Oleks PC\.virtualenvs\xednix-backend-NLhseXCO\Lib\site-packages\flask\app.py", line 919, in full_dispatch_request
    rv = self.handle_user_exception(e)
  File "C:\Users\Oleks PC\.virtualenvs\xednix-backend-NLhseXCO\Lib\site-packages\flask_cors\extension.py", line 176, in wrapped_function
    return cors_after_request(app.make_response(f(*args, **kwargs)))
                                                ~^^^^^^^^^^^^^^^^^
  File "C:\Users\Oleks PC\.virtualenvs\xednix-backend-NLhseXCO\Lib\site-packages\flask\app.py", line 917, in full_dispatch_request
    rv = self.dispatch_request()
  File "C:\Users\Oleks PC\.virtualenvs\xednix-backend-NLhseXCO\Lib\site-packages\flask\app.py", line 902, in dispatch_request
    return self.ensure_sync(self.view_functions[rule.endpoint])(**view_args)  # type: ignore[no-any-return]
           ~~~~~~~~~~~~~~~~~~~~~~~~~~~~~~~~~~~~~~~~~~~~~~~~~~~~^^^^^^^^^^^^^
  File "D:\projects\Xednix\xednix-backend\routes.py", line 23, in register
    if User.query.filter_by(username=username).first() or User.query.filter_by(email=email).first():
       ~~~~~~~~~~~~~~~~~~~~~~~~~~~~~~~~~~~~~~~~~~~~~^^
  File "C:\Users\Oleks PC\.virtualenvs\xednix-backend-NLhseXCO\Lib\site-packages\sqlalchemy\orm\query.py", line 2759, in first
    return self.limit(1)._iter().first()  # type: ignore
           ~~~~~~~~~~~~~~~~~~~^^
  File "C:\Users\Oleks PC\.virtualenvs\xednix-backend-NLhseXCO\Lib\site-packages\sqlalchemy\orm\query.py", line 2857, in _iter
    result: Union[ScalarResult[_T], Result[_T]] = self.session.execute(
                                                  ~~~~~~~~~~~~~~~~~~~~^
        statement,
        ^^^^^^^^^^
        params,
        ^^^^^^^
        execution_options={"_sa_orm_load_options": self.load_options},
        ^^^^^^^^^^^^^^^^^^^^^^^^^^^^^^^^^^^^^^^^^^^^^^^^^^^^^^^^^^^^^^
    )
    ^
  File "C:\Users\Oleks PC\.virtualenvs\xednix-backend-NLhseXCO\Lib\site-packages\sqlalchemy\orm\session.py", line 2365, in execute
    return self._execute_internal(
           ~~~~~~~~~~~~~~~~~~~~~~^
        statement,
        ^^^^^^^^^^
    ...<4 lines>...
        _add_event=_add_event,
        ^^^^^^^^^^^^^^^^^^^^^^
    )
    ^
  File "C:\Users\Oleks PC\.virtualenvs\xednix-backend-NLhseXCO\Lib\site-packages\sqlalchemy\orm\session.py", line 2251, in _execute_internal
    result: Result[Any] = compile_state_cls.orm_execute_statement(
                          ~~~~~~~~~~~~~~~~~~~~~~~~~~~~~~~~~~~~~~~^
        self,
        ^^^^^
    ...<4 lines>...
        conn,
        ^^^^^
    )
    ^
  File "C:\Users\Oleks PC\.virtualenvs\xednix-backend-NLhseXCO\Lib\site-packages\sqlalchemy\orm\context.py", line 306, in orm_execute_statement
    result = conn.execute(
        statement, params or {}, execution_options=execution_options
    )
  File "C:\Users\Oleks PC\.virtualenvs\xednix-backend-NLhseXCO\Lib\site-packages\sqlalchemy\engine\base.py", line 1419, in execute
    return meth(
        self,
        distilled_parameters,
        execution_options or NO_OPTIONS,
    )
  File "C:\Users\Oleks PC\.virtualenvs\xednix-backend-NLhseXCO\Lib\site-packages\sqlalchemy\sql\elements.py", line 526, in _execute_on_connection
    return connection._execute_clauseelement(
           ~~~~~~~~~~~~~~~~~~~~~~~~~~~~~~~~~^
        self, distilled_params, execution_options
        ^^^^^^^^^^^^^^^^^^^^^^^^^^^^^^^^^^^^^^^^^
    )
    ^
  File "C:\Users\Oleks PC\.virtualenvs\xednix-backend-NLhseXCO\Lib\site-packages\sqlalchemy\engine\base.py", line 1641, in _execute_clauseelement
    ret = self._execute_context(
        dialect,
    ...<8 lines>...
        cache_hit=cache_hit,
    )
  File "C:\Users\Oleks PC\.virtualenvs\xednix-backend-NLhseXCO\Lib\site-packages\sqlalchemy\engine\base.py", line 1846, in _execute_context
    return self._exec_single_context(
           ~~~~~~~~~~~~~~~~~~~~~~~~~^
        dialect, context, statement, parameters
        ^^^^^^^^^^^^^^^^^^^^^^^^^^^^^^^^^^^^^^^
    )
    ^
  File "C:\Users\Oleks PC\.virtualenvs\xednix-backend-NLhseXCO\Lib\site-packages\sqlalchemy\engine\base.py", line 1986, in _exec_single_context
    self._handle_dbapi_exception(
    ~~~~~~~~~~~~~~~~~~~~~~~~~~~~^
        e, str_statement, effective_parameters, cursor, context
        ^^^^^^^^^^^^^^^^^^^^^^^^^^^^^^^^^^^^^^^^^^^^^^^^^^^^^^^
    )
    ^
  File "C:\Users\Oleks PC\.virtualenvs\xednix-backend-NLhseXCO\Lib\site-packages\sqlalchemy\engine\base.py", line 2355, in _handle_dbapi_exception
    raise sqlalchemy_exception.with_traceback(exc_info[2]) from e
  File "C:\Users\Oleks PC\.virtualenvs\xednix-backend-NLhseXCO\Lib\site-packages\sqlalchemy\engine\base.py", line 1967, in _exec_single_context
    self.dialect.do_execute(
    ~~~~~~~~~~~~~~~~~~~~~~~^
        cursor, str_statement, effective_parameters, context
        ^^^^^^^^^^^^^^^^^^^^^^^^^^^^^^^^^^^^^^^^^^^^^^^^^^^^
    )
    ^
  File "C:\Users\Oleks PC\.virtualenvs\xednix-backend-NLhseXCO\Lib\site-packages\sqlalchemy\engine\default.py", line 951, in do_execute
    cursor.execute(statement, parameters)
    ~~~~~~~~~~~~~~^^^^^^^^^^^^^^^^^^^^^^^
sqlalchemy.exc.ProgrammingError: (psycopg2.errors.UndefinedTable) relation "user" does not exist
LINE 2: FROM "user" 
             ^

[SQL: SELECT "user".id AS user_id, "user".username AS user_username, "user".email AS user_email 
FROM "user" 
WHERE "user".username = %(username_1)s 
 LIMIT %(param_1)s]
[parameters: {'username_1': 'testuser', 'param_1': 1}]
(Background on this error at: https://sqlalche.me/e/20/f405)
2025-09-30 12:26:33,775 INFO: [31m[1mWARNING: This is a development server. Do not use it in a production deployment. Use a production WSGI server instead.[0m
 * Running on http://127.0.0.1:5000 [in C:\Users\Oleks PC\.virtualenvs\xednix-backend-NLhseXCO\Lib\site-packages\werkzeug\_internal.py:97]
2025-09-30 12:26:33,776 INFO: [33mPress CTRL+C to quit[0m [in C:\Users\Oleks PC\.virtualenvs\xednix-backend-NLhseXCO\Lib\site-packages\werkzeug\_internal.py:97]
